<?xml version="1.0"?>
<robot name="turtle_pi" xmlns:xacro="http://ros.org/wiki/xacro">

  <link name="base_footprint"/>

  <joint name="base_joint" type="fixed">
    <parent link="base_footprint"/>
    <child link="base_link" />
    <origin xyz="0 0 0.010" rpy="0 0 0"/>
  </joint>

  <link name="base_link">
    <visual>
      <geometry>
        <mesh filename="package://turtle_pi_description/urdf/meshes/turtle_pi_chassis.dae"/>
      </geometry>
    </visual>
    <inertial>
      <mass value="1"/>
      <inertia ixx="0.0049669" ixy="0.0" ixz="0.0" iyy="0.0016556" iyz="0.0" izz="0.0049669"/>
    </inertial>
    <collision>
      <origin xyz="0 0 0" rpy="0 0 0"/>
      <geometry>
        <mesh filename="package://turtle_pi_description/urdf/meshes/turtle_pi_chassis_collision.stl"/>
      </geometry>
    </collision>
  </link>

  <gazebo reference="base_link">
    <mu1 value="0.1"/>
    <mu2 value="0.1"/>
    <kp value="10000000.0" />
    <kd value="1.0" />
  </gazebo>

  <link name="left_wheel">
    <visual>
      <origin xyz="0 0 0" rpy="0 0 0"/>
      <geometry>
        <mesh filename="package://turtle_pi_description/urdf/meshes/turtle_pi_wheel.dae"/>
      </geometry>
    </visual>
    <inertial>
      <mass value="0.1"/>
      <inertia ixx="0.001" ixy="0.0" ixz="0.0" iyy="0.001" iyz="0.0" izz="0.001"/>
    </inertial>
    <collision>
      <origin xyz="-0.0175 0 0" rpy="0 1.57079632679 0"/>
      <geometry>
        <cylinder length="0.025" radius="0.035"/>
      </geometry>
    </collision>
  </link>

  <link name="camera_link">
    <visual>
      <origin xyz="0 0 0" rpy="0 0 0"/>
      <geometry>
        <box size="0.01 0.01 0.01"/>
      </geometry>>
    </visual>
  </link>
  
  <link name="right_wheel">
    <visual>
      <origin rpy="0 3.1415 0" xyz="0 0 0"/>
      <geometry>
        <mesh filename="package://turtle_pi_description/urdf/meshes/turtle_pi_wheel.dae"/>
      </geometry>
    </visual>
    <inertial>
      <mass value="0.1"/>
      <inertia ixx="0.001" ixy="0.0" ixz="0.0" iyy="0.001" iyz="0.0" izz="0.001"/>
    </inertial>
    <collision>
      <origin xyz="0.0175 0 0" rpy="0 -1.57079632679 0"/>
      <geometry>
        <cylinder length="0.025" radius="0.035"/>
      </geometry>
    </collision>
  </link>
  
  <joint name="left_wheel_joint" type="continuous">
    <axis xyz="-1 0 0"/>
    <origin rpy="0 0 0" xyz="-0.050850 0.085775 -0.011100"/>
    <parent link="base_link"/>
    <child link="left_wheel"/>
  </joint>

  <transmission name="left_wheel_trans">
    <type>transmission_interface/SimpleTransmission</type>
    <actuator name="left_wheel_motor">
      <hardwareInterface>EffortJointInterface</hardwareInterface>
      <mechanicalReduction>1</mechanicalReduction>
    </actuator>
    <joint name="left_wheel_joint">
      <hardwareInterface>hardware_interface/VelocityJointInterface</hardwareInterface>
    </joint>
  </transmission>

  <joint name="right_wheel_joint" type="continuous">
    <axis xyz="-1 0 0"/>
    <origin rpy="0 0 0" xyz="0.050850 0.085775 -0.011100"/>
    <parent link="base_link"/>
    <child link="right_wheel"/>
  </joint>

  <transmission name="right_wheel_trans">
    <type>transmission_interface/SimpleTransmission</type>
    <actuator name="right_wheel_motor">
      <hardwareInterface>EffortJointInterface</hardwareInterface>
      <mechanicalReduction>1</mechanicalReduction>
    </actuator>
    <joint name="right_wheel_joint">
      <hardwareInterface>hardware_interface/VelocityJointInterface</hardwareInterface>
    </joint>
  </transmission>

  <xacro:property name="M_PI" value="3.1415926535897931" />

  <joint name="camera_joint" type="fixed">
    <origin rpy="0 0 ${M_PI/2}" xyz="0 0.15 0.05"/>
    <parent link="base_link"/>
    <child link="camera_link"/>
  </joint>

  <gazebo reference="camera_link">
    <sensor type="camera" name="camera_camera_sensor">
      <update_rate>30.0</update_rate>
      <camera>
        <pose>0.035 0.1 0.078 0 0 0</pose>
        <horizontal_fov>${85 * M_PI/180.0}</horizontal_fov>
        <image>
          <format>R8G8B8</format>
          <width>640</width>
          <height>480</height>
        </image>
        <clip>
          <near>0.01</near>
          <far>100</far>
        </clip>
      </camera>

      <plugin name="camera_camera_controller" filename="libgazebo_ros_camera.so">
        <alwaysOn>true</alwaysOn>
        <updateRate>10.0</updateRate>
        <cameraName>turtle_pi/camera</cameraName>
        <imageTopicName>image_raw</imageTopicName>
        <cameraInfoTopicName>camera_info</cameraInfoTopicName>
        <frameName>camera_link</frameName>
        <hackBaseline>0.07</hackBaseline>
        <distortionK1>0.0</distortionK1>
        <distortionK2>0.0</distortionK2>
        <distortionK3>0.0</distortionK3>
        <distortionT1>0.0</distortionT1>
        <distortionT2>0.0</distortionT2>
      </plugin>
    </sensor>
  </gazebo>

  <gazebo reference="left_wheel">
    <mu1 value="200.0"/>
    <mu2 value="100.0"/>
    <kp value="10000000.0" />
    <kd value="1.0" />
  </gazebo>

  <gazebo reference="right_wheel">
    <mu1 value="200.0"/>
    <mu2 value="100.0"/>
    <kp value="10000000.0" />
    <kd value="1.0" />
  </gazebo>

  <gazebo>
    <plugin name="gazebo_ros_control" filename="libgazebo_ros_control.so">
      <robotNamespace>/</robotNamespace>
      <robotSimType>gazebo_ros_control/DefaultHWSim</robotSimType>
    </plugin>
  </gazebo>

  <gazebo>
    <plugin name="turtle_pi_diff_drive" filename="libgazebo_ros_diff_drive.so">
      <commandTopic>cmd_vel</commandTopic>
      <odometryTopic>odom</odometryTopic>
      <odometryFrame>odom</odometryFrame>
      <odometrySource>world</odometrySource>
      <publishOdomTF>true</publishOdomTF>
      <robotBaseFrame>base_footprint</robotBaseFrame>
      <publishWheelTF>false</publishWheelTF>
      <publishTf>true</publishTf>
      <publishWheelJointState>true</publishWheelJointState>
      <legacyMode>false</legacyMode>
      <updateRate>30</updateRate>
      <leftJoint>left_wheel_joint</leftJoint>
      <rightJoint>right_wheel_joint</rightJoint>
      <wheelSeparation>0.287</wheelSeparation>
      <wheelDiameter>0.066</wheelDiameter>
      <wheelAcceleration>1</wheelAcceleration>
      <wheelTorque>10</wheelTorque>
      <rosDebugLevel>na</rosDebugLevel>
    </plugin>
  </gazebo>
</robot>